<mujoco model="ant">
  <compiler angle="degree" coordinate="local" inertiafromgeom="true"/>
  <option integrator="RK4" timestep="0.01"/>
  <custom>
    <numeric data="0.0 0.0 0.55 1.0 0.0 0.0 0.0 0.0 1.0 0.0 -1.0 0.0 -1.0 0.0 1.0" name="init_qpos"/>
  </custom>
  <default>
    <joint armature="1" damping="1" limited="true"/>
    <geom conaffinity="0" condim="3" density="5.0" friction="1 0.5 0.5" margin="0.01" rgba="0.8 0.6 0.4 1"/>
  </default>

  <default class="rangefinder">
      <site type="capsule" size=".005 .01" group="4"/>
  </default>

  <asset>
    <texture builtin="gradient" height="100" rgb1="1 1 1" rgb2="0 0 0" type="skybox" width="100"/>
    <texture builtin="flat" height="1278" mark="cross" markrgb="1 1 1" name="texgeom" random="0.01" rgb1="0.8 0.6 0.4" rgb2="0.8 0.6 0.4" type="cube" width="127"/>
    <texture builtin="checker" height="100" name="texplane" rgb1="0 0 0" rgb2="0.8 0.8 0.8" type="2d" width="100"/>
    <material name="MatPlane" reflectance="0.5" shininess="1" specular="1" texrepeat="60 60" texture="texplane"/>
    <material name="geom" texture="texgeom" texuniform="true"/>
  </asset>
  <worldbody>
    <light cutoff="100" diffuse="1 1 1" dir="-0 0 -1.3" directional="true" exponent="1" pos="0 0 1.3" specular=".1 .1 .1"/>
    <geom conaffinity="1" condim="3" material="" name="floor" pos="0 0 0" rgba="0.8 0.9 0.8 1" size="40 40 40" type="plane"/>

    <body name="torso" pos="0 0 0.75">
      <camera name="track" mode="trackcom" pos="0 -3 0.3" xyaxes="1 0 0 0 0 1"/>

      <site name="rf_00" class="rangefinder" pos="0 0 0.81" quat="0.44 1 0 0"/>
      <site name="rf_01" class="rangefinder" pos="0 0 0.81" quat="0.32 1 0 0.32"/>
      <site name="rf_02" class="rangefinder" pos="0 0 0.81" quat="0 1 0 0.44"/>
      <site name="rf_03" class="rangefinder" pos="0 0 0.81" quat="-0.32 1 0 0.32"/>
      <site name="rf_04" class="rangefinder" pos="0 0 0.81" quat="0 1 0 -0.44"/>
      <site name="rf_05" class="rangefinder" pos="0 0 0.81" quat="-0.32 1 0 -0.32"/>
      <site name="rf_06" class="rangefinder" pos="0 0 0.81" quat="-0.44 1 0 0"/>      
      <site name="rf_07" class="rangefinder" pos="0 0 0.81" quat="0.32 1 0 -0.32"/>

      <site name="rf_10" class="rangefinder" pos="0 0 0.81" quat="0.55 1 0 0"/>
      <site name="rf_11" class="rangefinder" pos="0 0 0.81" quat="0.39 1 0 0.39"/>
      <site name="rf_12" class="rangefinder" pos="0 0 0.81" quat="0 1 0 0.55"/>
      <site name="rf_13" class="rangefinder" pos="0 0 0.81" quat="-0.39 1 0 0.39"/>
      <site name="rf_14" class="rangefinder" pos="0 0 0.81" quat="0 1 0 -0.55"/>
      <site name="rf_15" class="rangefinder" pos="0 0 0.81" quat="-0.39 1 0 -0.39"/>
      <site name="rf_16" class="rangefinder" pos="0 0 0.81" quat="-0.55 1 0 0"/>      
      <site name="rf_17" class="rangefinder" pos="0 0 0.81" quat="0.39 1 0 -0.39"/>
      

      <geom name="torso_geom" pos="0 0 0" size="0.25" type="sphere"/>
      <joint armature="0" damping="0" limited="false" margin="0.01" name="root" pos="0 0 0" type="free"/>
      <body name="front_left_leg" pos="0 0 0">
        <geom fromto="0.0 0.0 0.0 0.2 0.2 0.0" name="aux_1_geom" size="0.08" type="capsule"/>
        <body name="aux_1" pos="0.2 0.2 0">
          <joint axis="0 0 1" name="hip_1" pos="0.0 0.0 0.0" range="-30 30" type="hinge"/>
          <geom fromto="0.0 0.0 0.0 0.2 0.2 0.0" name="left_leg_geom" size="0.08" type="capsule"/>
          <body pos="0.2 0.2 0">
            <joint axis="-1 1 0" name="ankle_1" pos="0.0 0.0 0.0" range="30 70" type="hinge"/>
            <geom fromto="0.0 0.0 0.0 0.4 0.4 0.0" name="left_ankle_geom" size="0.08" type="capsule"/>
          </body>
        </body>
      </body>
      <body name="front_right_leg" pos="0 0 0">
        <geom fromto="0.0 0.0 0.0 -0.2 0.2 0.0" name="aux_2_geom" size="0.08" type="capsule"/>
        <body name="aux_2" pos="-0.2 0.2 0">
          <joint axis="0 0 1" name="hip_2" pos="0.0 0.0 0.0" range="-30 30" type="hinge"/>
          <geom fromto="0.0 0.0 0.0 -0.2 0.2 0.0" name="right_leg_geom" size="0.08" type="capsule"/>
          <body pos="-0.2 0.2 0">
            <joint axis="1 1 0" name="ankle_2" pos="0.0 0.0 0.0" range="-70 -30" type="hinge"/>
            <geom fromto="0.0 0.0 0.0 -0.4 0.4 0.0" name="right_ankle_geom" size="0.08" type="capsule"/>
          </body>
        </body>
      </body>
      <body name="back_leg" pos="0 0 0">
        <geom fromto="0.0 0.0 0.0 -0.2 -0.2 0.0" name="aux_3_geom" size="0.08" type="capsule"/>
        <body name="aux_3" pos="-0.2 -0.2 0">
          <joint axis="0 0 1" name="hip_3" pos="0.0 0.0 0.0" range="-30 30" type="hinge"/>
          <geom fromto="0.0 0.0 0.0 -0.2 -0.2 0.0" name="back_leg_geom" size="0.08" type="capsule"/>
          <body pos="-0.2 -0.2 0">
            <joint axis="-1 1 0" name="ankle_3" pos="0.0 0.0 0.0" range="-70 -30" type="hinge"/>
            <geom fromto="0.0 0.0 0.0 -0.4 -0.4 0.0" name="third_ankle_geom" size="0.08" type="capsule"/>
          </body>
        </body>
      </body>
      <body name="right_back_leg" pos="0 0 0">
        <geom fromto="0.0 0.0 0.0 0.2 -0.2 0.0" name="aux_4_geom" size="0.08" type="capsule"/>
        <body name="aux_4" pos="0.2 -0.2 0">
          <joint axis="0 0 1" name="hip_4" pos="0.0 0.0 0.0" range="-30 30" type="hinge"/>
          <geom fromto="0.0 0.0 0.0 0.2 -0.2 0.0" name="rightback_leg_geom" size="0.08" type="capsule"/>
          <body pos="0.2 -0.2 0">
            <joint axis="1 1 0" name="ankle_4" pos="0.0 0.0 0.0" range="30 70" type="hinge"/>
            <geom fromto="0.0 0.0 0.0 0.4 -0.4 0.0" name="fourth_ankle_geom" size="0.08" type="capsule"/>
          </body>
        </body>
      </body>
    </body>

    <body name="target" pos="2 -2 .25">
      <geom conaffinity="0" contype="0" name="target" pos="0 0 0" rgba="0.2 0.9 0.2 1" size=".5" type="sphere"/>
    </body>

    <body name="highlevel" pos="-2 2 20.0">
      <geom conaffinity="0" contype="0" name="highlevel" pos="0 0 0" rgba="0.9 0.2 0.2 1" size=".3" type="sphere"/>
    </body>

  </worldbody>
  <actuator>
    <motor ctrllimited="true" ctrlrange="-1.0 1.0" joint="hip_4" gear="150"/>
    <motor ctrllimited="true" ctrlrange="-1.0 1.0" joint="ankle_4" gear="150"/>
    <motor ctrllimited="true" ctrlrange="-1.0 1.0" joint="hip_1" gear="150"/>
    <motor ctrllimited="true" ctrlrange="-1.0 1.0" joint="ankle_1" gear="150"/>
    <motor ctrllimited="true" ctrlrange="-1.0 1.0" joint="hip_2" gear="150"/>
    <motor ctrllimited="true" ctrlrange="-1.0 1.0" joint="ankle_2" gear="150"/>
    <motor ctrllimited="true" ctrlrange="-1.0 1.0" joint="hip_3" gear="150"/>
    <motor ctrllimited="true" ctrlrange="-1.0 1.0" joint="ankle_3" gear="150"/>
  </actuator>

  <sensor>
    <rangefinder name="rf_00" site="rf_00"/>
    <rangefinder name="rf_01" site="rf_01"/>
    <rangefinder name="rf_02" site="rf_02"/>
    <rangefinder name="rf_03" site="rf_03"/>
    <rangefinder name="rf_04" site="rf_04"/>    
    <rangefinder name="rf_05" site="rf_05"/>
    <rangefinder name="rf_06" site="rf_06"/>    
    <rangefinder name="rf_07" site="rf_07"/>

    <rangefinder name="rf_10" site="rf_10"/>
    <rangefinder name="rf_11" site="rf_11"/>
    <rangefinder name="rf_12" site="rf_12"/>
    <rangefinder name="rf_13" site="rf_13"/>
    <rangefinder name="rf_14" site="rf_14"/>    
    <rangefinder name="rf_15" site="rf_15"/>
    <rangefinder name="rf_16" site="rf_16"/>    
    <rangefinder name="rf_17" site="rf_17"/>

    
  </sensor>

</mujoco>