<mujoco model="reacher">
	<compiler angle="radian" inertiafromgeom="true"/>
	<default>
		<joint armature="1" damping="1" limited="true"/>
		<geom friction="1 0.1 0.1" contype="0" conaffinity="0" rgba="0.7 0.7 0 1"/>
	</default>
	<option gravity="0 0 -9.81" integrator="RK4" timestep="0.01"/>
	<worldbody>
		<!-- Arena -->
		<geom conaffinity="1" name="ground" pos="0 0 0" rgba="0.9 0.9 0.9 1" size="1 1 10" type="plane"/>
		<!-- Arm -->
		<body name="fingertip" pos="0.2 0 .01">
			<joint name="root_x" type="slide"  pos="0 0 0" axis="1 0 0" ref="0.2" range="-.3 .3"/>
			<joint name="root_y" type="slide"  pos="0 0 0" axis="0 1 0" range="-.3 .3"/>
			<geom conaffinity="1" contype="1" name="fingertip" pos="0 0 0" rgba="0.0 0.8 0.6 1" size=".015" type="sphere"/>
			<geom conaffinity="1" contype="1" name="peg" mass="0.00001" type="box" pos="0 -0.025 0" size="0.005 0.025 0.005" rgba="0.0 0.8 0.6 1"/>
			<body name="peg" pos="0 -0.05 0">
				<geom conaffinity="1" contype="1" name="pegtip" type="sphere" size="0.002"/>
			</body>
		</body>
  
		<body name="highlevel" pos="0.2 -0.04 0.01">
      		<geom conaffinity="0" contype="0" name="highlevel" pos="0 0 0" rgba="0.2 0.9 0.2 1" size=".01" type="sphere"/>
    	</body>

	
	</worldbody>
	<actuator>
		<motor joint='root_x' ctrlrange="-1 1" ctrllimited="true" gear="125.0"/>
    	<motor joint='root_y' ctrlrange="-1 1" ctrllimited="true" gear="125.0" />
	</actuator>
</mujoco>