<mujoco model="reacher">
	<compiler angle="radian" inertiafromgeom="true"/>
	<default>
		<joint type="hinge" axis="0 0 1" limited="true" range="-.29 .29" damping="1"/>
		<motor gear="10" ctrlrange="-0.7 0.7" ctrllimited="true"/>
  </default>
	<option gravity="0 0 -9.81" integrator="RK4" timestep="0.01"/>
	<worldbody>
		<!-- Arena -->
		<geom conaffinity="1" name="ground" pos="0 0 0" rgba="0.9 0.9 0.9 1" size="1 1 10" type="plane"/>
		<geom conaffinity="0" fromto="-.3 -.3 .01 .3 -.3 .01" name="sideS" rgba="0.9 0.4 0.6 1" size=".02" type="capsule"/>
		<geom conaffinity="0" fromto=" .3 -.3 .01 .3  .3 .01" name="sideE" rgba="0.9 0.4 0.6 1" size=".02" type="capsule"/>
		<geom conaffinity="0" fromto="-.3  .3 .01 .3  .3 .01" name="sideN" rgba="0.9 0.4 0.6 1" size=".02" type="capsule"/>
		<geom conaffinity="0" fromto="-.3 -.3 .01 -.3 .3 .01" name="sideW" rgba="0.9 0.4 0.6 1" size=".02" type="capsule"/>
		<!-- Arm -->
		<body name="fingertip" pos="0.2 0 .01">
			<joint name="root_x" type="slide"  pos="0 0 0" axis="1 0 0" ref="0.2"/>
			<joint name="root_y" type="slide"  pos="0 0 0" axis="0 1 0" />
			<geom conaffinity="1" contype="1" name="fingertip" pos="0 0 0" rgba="0.0 0.8 0.6 1" size=".015" type="sphere"/>
		</body>
		<!-- Target -->
		<body name="dest" pos="-0.08 -0.08 0.02">
      		<geom conaffinity="0" contype="0" name="dest" pos="0 0 0" rgba="0.2 0.2 0.9 0.3" size=".02 .02 .02" type="box"/>
    	</body>

		<body name="target" pos="0.12 -0.08 .018">
			<joint armature="0" axis="1 0 0" damping="0" limited="true" name="target_x" pos="0 0 0" range="-.27 .27" ref="0.12" stiffness="0" type="slide"/>
			<joint armature="0" axis="0 1 0" damping="0" limited="true" name="target_y" pos="0 0 0" range="-.27 .27" ref="-.08" stiffness="0" type="slide"/>
			<geom conaffinity="0" contype="1" name="target" pos="0 0 0" rgba="0.9 0.2 0.2 1" size=".02 .02 .02" mass="0.01" type="box"/>
		</body>

		<body name="highlevel" pos="0.2 -0.04 0.01">
      		<geom conaffinity="0" contype="0" name="highlevel" pos="0 0 0" rgba="0.2 0.9 0.2 1" size=".01" type="sphere"/>
    	</body>

	</worldbody>
	<tendon>
		<fixed name="t1">
		<joint joint="root_x" coef="1"/>
		<joint joint="root_y" coef="0"/>
		</fixed>
		<fixed name="t2">
		<joint joint="root_x" coef="0"/>
		<joint joint="root_y" coef="1"/>
		</fixed>
	</tendon>

	<actuator>
		<motor name="t1" tendon="t1"/>
		<motor name="t2" tendon="t2"/>
	</actuator>
</mujoco>